Workbook

Sheet Q1 2026 Daily Tracker
A1: Date | B1: Day | C1: Agentic AI (hrs) | D1: Work (hrs) | E1: Side Hustle (hrs) | F1: Reading (pages) | G1: Gym (✓/min) | H1: Sleep (hrs) | I1: Water (L) | J1: Meditation (min) | K1: Notes/Wins | L1: Score
A2: January 2026
A3: Jan 01 | B3: Thu | L3: =IF(COUNTA(C3:J3)=0,"",ROUND((C3>=2)*15+(D3>=6)*10+(E3>=1)*15+(F3>=10)*10+(LEN(G3)>0)*15+(H3>=7)*10+(I3>=2)*10+(J3>=10)*15,0))
A4: Jan 02 | B4: Fri | L4: =IF(COUNTA(C4:J4)=0,"",ROUND((C4>=2)*15+(D4>=6)*10+(E4>=1)*15+(F4>=10)*10+(LEN(G4)>0)*15+(H4>=7)*10+(I4>=2)*10+(J4>=10)*15,0))
A5: Jan 03 | B5: Sat | L5: =IF(COUNTA(C5:J5)=0,"",ROUND((C5>=2)*15+(D5>=6)*10+(E5>=1)*15+(F5>=10)*10+(LEN(G5)>0)*15+(H5>=7)*10+(I5>=2)*10+(J5>=10)*15,0))
A6: Jan 04 | B6: Sun | L6: =IF(COUNTA(C6:J6)=0,"",ROUND((C6>=2)*15+(D6>=6)*10+(E6>=1)*15+(F6>=10)*10+(LEN(G6)>0)*15+(H6>=7)*10+(I6>=2)*10+(J6>=10)*15,0))
A7: Jan 05 | B7: Mon | L7: =IF(COUNTA(C7:J7)=0,"",ROUND((C7>=2)*15+(D7>=6)*10+(E7>=1)*15+(F7>=10)*10+(LEN(G7)>0)*15+(H7>=7)*10+(I7>=2)*10+(J7>=10)*15,0))
A8: Jan 06 | B8: Tue | L8: =IF(COUNTA(C8:J8)=0,"",ROUND((C8>=2)*15+(D8>=6)*10+(E8>=1)*15+(F8>=10)*10+(LEN(G8)>0)*15+(H8>=7)*10+(I8>=2)*10+(J8>=10)*15,0))
A9: Jan 07 | B9: Wed | L9: =IF(COUNTA(C9:J9)=0,"",ROUND((C9>=2)*15+(D9>=6)*10+(E9>=1)*15+(F9>=10)*10+(LEN(G9)>0)*15+(H9>=7)*10+(I9>=2)*10+(J9>=10)*15,0))
A10: Jan 08 | B10: Thu | L10: =IF(COUNTA(C10:J10)=0,"",ROUND((C10>=2)*15+(D10>=6)*10+(E10>=1)*15+(F10>=10)*10+(LEN(G10)>0)*15+(H10>=7)*10+(I10>=2)*10+(J10>=10)*15,0))
A11: Jan 09 | B11: Fri | L11: =IF(COUNTA(C11:J11)=0,"",ROUND((C11>=2)*15+(D11>=6)*10+(E11>=1)*15+(F11>=10)*10+(LEN(G11)>0)*15+(H11>=7)*10+(I11>=2)*10+(J11>=10)*15,0))
A12: Jan 10 | B12: Sat | L12: =IF(COUNTA(C12:J12)=0,"",ROUND((C12>=2)*15+(D12>=6)*10+(E12>=1)*15+(F12>=10)*10+(LEN(G12)>0)*15+(H12>=7)*10+(I12>=2)*10+(J12>=10)*15,0))
A13: Jan 11 | B13: Sun | L13: =IF(COUNTA(C13:J13)=0,"",ROUND((C13>=2)*15+(D13>=6)*10+(E13>=1)*15+(F13>=10)*10+(LEN(G13)>0)*15+(H13>=7)*10+(I13>=2)*10+(J13>=10)*15,0))
A14: Jan 12 | B14: Mon | L14: =IF(COUNTA(C14:J14)=0,"",ROUND((C14>=2)*15+(D14>=6)*10+(E14>=1)*15+(F14>=10)*10+(LEN(G14)>0)*15+(H14>=7)*10+(I14>=2)*10+(J14>=10)*15,0))
... A33: Jan 31 | B33: Sat | L33: =IF(COUNTA(C33:J33)=0,"",ROUND((C33>=2)*15+(D33>=6)*10+(E33>=1)*15+(F33>=10)*10+(LEN(G33)>0)*15+(H33>=7)*10+(I33>=2)*10+(J33>=10)*15,0))
A34: February 2026
A35: Feb 01 | B35: Sun | L35: =IF(COUNTA(C35:J35)=0,"",ROUND((C35>=2)*15+(D35>=6)*10+(E35>=1)*15+(F35>=10)*10+(LEN(G35)>0)*15+(H35>=7)*10+(I35>=2)*10+(J35>=10)*15,0))
A36: Feb 02 | B36: Mon | L36: =IF(COUNTA(C36:J36)=0,"",ROUND((C36>=2)*15+(D36>=6)*10+(E36>=1)*15+(F36>=10)*10+(LEN(G36)>0)*15+(H36>=7)*10+(I36>=2)*10+(J36>=10)*15,0))
A37: Feb 03 | B37: Tue | L37: =IF(COUNTA(C37:J37)=0,"",ROUND((C37>=2)*15+(D37>=6)*10+(E37>=1)*15+(F37>=10)*10+(LEN(G37)>0)*15+(H37>=7)*10+(I37>=2)*10+(J37>=10)*15,0))
A38: Feb 04 | B38: Wed | L38: =IF(COUNTA(C38:J38)=0,"",ROUND((C38>=2)*15+(D38>=6)*10+(E38>=1)*15+(F38>=10)*10+(LEN(G38)>0)*15+(H38>=7)*10+(I38>=2)*10+(J38>=10)*15,0))
A39: Feb 05 | B39: Thu | L39: =IF(COUNTA(C39:J39)=0,"",ROUND((C39>=2)*15+(D39>=6)*10+(E39>=1)*15+(F39>=10)*10+(LEN(G39)>0)*15+(H39>=7)*10+(I39>=2)*10+(J39>=10)*15,0))
A40: Feb 06 | B40: Fri | L40: =IF(COUNTA(C40:J40)=0,"",ROUND((C40>=2)*15+(D40>=6)*10+(E40>=1)*15+(F40>=10)*10+(LEN(G40)>0)*15+(H40>=7)*10+(I40>=2)*10+(J40>=10)*15,0))
A41: Feb 07 | B41: Sat | L41: =IF(COUNTA(C41:J41)=0,"",ROUND((C41>=2)*15+(D41>=6)*10+(E41>=1)*15+(F41>=10)*10+(LEN(G41)>0)*15+(H41>=7)*10+(I41>=2)*10+(J41>=10)*15,0))
A42: Feb 08 | B42: Sun | L42: =IF(COUNTA(C42:J42)=0,"",ROUND((C42>=2)*15+(D42>=6)*10+(E42>=1)*15+(F42>=10)*10+(LEN(G42)>0)*15+(H42>=7)*10+(I42>=2)*10+(J42>=10)*15,0))
A43: Feb 09 | B43: Mon | L43: =IF(COUNTA(C43:J43)=0,"",ROUND((C43>=2)*15+(D43>=6)*10+(E43>=1)*15+(F43>=10)*10+(LEN(G43)>0)*15+(H43>=7)*10+(I43>=2)*10+(J43>=10)*15,0))
A44: Feb 10 | B44: Tue | L44: =IF(COUNTA(C44:J44)=0,"",ROUND((C44>=2)*15+(D44>=6)*10+(E44>=1)*15+(F44>=10)*10+(LEN(G44)>0)*15+(H44>=7)*10+(I44>=2)*10+(J44>=10)*15,0))
A45: Feb 11 | B45: Wed | L45: =IF(COUNTA(C45:J45)=0,"",ROUND((C45>=2)*15+(D45>=6)*10+(E45>=1)*15+(F45>=10)*10+(LEN(G45)>0)*15+(H45>=7)*10+(I45>=2)*10+(J45>=10)*15,0))
A46: Feb 12 | B46: Thu | L46: =IF(COUNTA(C46:J46)=0,"",ROUND((C46>=2)*15+(D46>=6)*10+(E46>=1)*15+(F46>=10)*10+(LEN(G46)>0)*15+(H46>=7)*10+(I46>=2)*10+(J46>=10)*15,0))
... A62: Feb 28 | B62: Sat | L62: =IF(COUNTA(C62:J62)=0,"",ROUND((C62>=2)*15+(D62>=6)*10+(E62>=1)*15+(F62>=10)*10+(LEN(G62)>0)*15+(H62>=7)*10+(I62>=2)*10+(J62>=10)*15,0))
A63: March 2026
A64: Mar 01 | B64: Sun | L64: =IF(COUNTA(C64:J64)=0,"",ROUND((C64>=2)*15+(D64>=6)*10+(E64>=1)*15+(F64>=10)*10+(LEN(G64)>0)*15+(H64>=7)*10+(I64>=2)*10+(J64>=10)*15,0))
A65: Mar 02 | B65: Mon | L65: =IF(COUNTA(C65:J65)=0,"",ROUND((C65>=2)*15+(D65>=6)*10+(E65>=1)*15+(F65>=10)*10+(LEN(G65)>0)*15+(H65>=7)*10+(I65>=2)*10+(J65>=10)*15,0))
A66: Mar 03 | B66: Tue | L66: =IF(COUNTA(C66:J66)=0,"",ROUND((C66>=2)*15+(D66>=6)*10+(E66>=1)*15+(F66>=10)*10+(LEN(G66)>0)*15+(H66>=7)*10+(I66>=2)*10+(J66>=10)*15,0))
A67: Mar 04 | B67: Wed | L67: =IF(COUNTA(C67:J67)=0,"",ROUND((C67>=2)*15+(D67>=6)*10+(E67>=1)*15+(F67>=10)*10+(LEN(G67)>0)*15+(H67>=7)*10+(I67>=2)*10+(J67>=10)*15,0))
A68: Mar 05 | B68: Thu | L68: =IF(COUNTA(C68:J68)=0,"",ROUND((C68>=2)*15+(D68>=6)*10+(E68>=1)*15+(F68>=10)*10+(LEN(G68)>0)*15+(H68>=7)*10+(I68>=2)*10+(J68>=10)*15,0))
A69: Mar 06 | B69: Fri | L69: =IF(COUNTA(C69:J69)=0,"",ROUND((C69>=2)*15+(D69>=6)*10+(E69>=1)*15+(F69>=10)*10+(LEN(G69)>0)*15+(H69>=7)*10+(I69>=2)*10+(J69>=10)*15,0))
A70: Mar 07 | B70: Sat | L70: =IF(COUNTA(C70:J70)=0,"",ROUND((C70>=2)*15+(D70>=6)*10+(E70>=1)*15+(F70>=10)*10+(LEN(G70)>0)*15+(H70>=7)*10+(I70>=2)*10+(J70>=10)*15,0))
A71: Mar 08 | B71: Sun | L71: =IF(COUNTA(C71:J71)=0,"",ROUND((C71>=2)*15+(D71>=6)*10+(E71>=1)*15+(F71>=10)*10+(LEN(G71)>0)*15+(H71>=7)*10+(I71>=2)*10+(J71>=10)*15,0))
A72: Mar 09 | B72: Mon | L72: =IF(COUNTA(C72:J72)=0,"",ROUND((C72>=2)*15+(D72>=6)*10+(E72>=1)*15+(F72>=10)*10+(LEN(G72)>0)*15+(H72>=7)*10+(I72>=2)*10+(J72>=10)*15,0))
A73: Mar 10 | B73: Tue | L73: =IF(COUNTA(C73:J73)=0,"",ROUND((C73>=2)*15+(D73>=6)*10+(E73>=1)*15+(F73>=10)*10+(LEN(G73)>0)*15+(H73>=7)*10+(I73>=2)*10+(J73>=10)*15,0))
...

Sheet Daily Routine
A1: ⏰ DAILY ROUTINE - Q1 2026
A2: WEEKDAYS | C2: WEEKENDS
A3: Sunday - Thursday | C3: Friday - Saturday
A4: 6:00 AM | B4: 🌅 Wake Up & Hydrate | C4: 8:00 AM | D4: 🌅 Wake Up & Hydrate
A5: 6:00 - 6:15 AM | B5: 🧘 Meditation (15 min) | C5: 8:00 - 9:30 AM | D5: 🧘 Meditation & Stretching (90 min)
A6: 6:15 - 7:00 AM | B6: 🧘‍♂️ Yoga (45 min) | D6: • Longer, deeper practice
A7: 7:00 - 7:30 AM | B7: 🚿 Freshen Up & Breakfast
C8: 9:30 - 10:30 AM | D8: 🚿 Freshen Up & Pooja
A9: 8:00 - 10:00 AM | B9: 🚀 AGENTIC AI LEARNING (2 hrs) | D9: • Spiritual practice/gratitude
B10: • Build daily task from learning plan
B11: • Ship working code | C11: 10:30 - 11:00 AM | D11: 🍳 Breakfast
A13: 10:30 AM - 2:00 PM | B13: 💼 WORK (3.5 hrs) | C13: 11:30 AM - 1:30 PM | D13: 🚀 AGENTIC AI LEARNING (2 hrs)
B14: • Professional work/projects | D14: • Weekend project building
D15: • Experiment & explore
A16: 2:00 - 4:00 PM | B16: 🍽️ Lunch & Rest Break
B17: • Eat mindfully, power nap if needed | C17: 1:30 - 5:00 PM | D17: 😌 Afternoon Relax & Free Time
D18: • Social time, hobbies, rest
A19: 4:15 - 6:15 PM | B19: 💻 PYTHON PROGRAMMING (2 hrs) | D19: • Netflix, gaming, friends
B20: • Practice coding, solve problems
B21: • LeetCode/side project work | C21: 5:00 - 6:30 PM | D21: 📚 READING (90 min)
D22: • Catch up on weekly reading goal
A23: 6:15 - 7:00 PM | B23: 📚 READING (45 min)
B24: • 10+ pages minimum | C24: 6:30 - 9:00 PM | D24: 🎉 Go Out & Chill
D25: • Social activities, restaurants
A26: 7:00 - 8:00 PM | B26: 😌 Relax & Unwind | D26: • Entertainment, fun
A28: 8:00 - 8:30 PM | B28: 🍽️ Dinner | C28: 9:00 - 9:30 PM | D28: 🍽️ Dinner (if not out)
A30: 8:30 - 9:00 PM | B30: 🚶‍♂️ Evening Walk | C30: 9:30 - 10:00 PM | D30: 📔 Journaling
B31: • 15-20 min outdoor walk | D31: • Weekly reflection
D32: • Review progress
A33: 9:00 - 9:30 PM | B33: 📔 Journaling & Reflection
B34: • Fill habit tracker | C34: 10:30 PM | D34: 😴 Sleep
B35: • Write daily wins
B36: • Plan tomorrow
A37: 📊 WEEKLY TIME BREAKDOWN
A38: 🚀 Agentic AI Learning: | B38: 12 hours/week (2hrs × 6 days) | C38: Primary Goal
A39: 💻 Python Programming: | B39: 10 hours/week (2hrs × 5 days) | C39: Skill Building
A40: 💼 Work: | B40: 17.5 hours/week (3.5hrs × 5 days) | C40: Career
A41: 📚 Reading: | B41: 7+ hours/week | C41: Knowledge
A42: 🧘 Meditation/Yoga: | B42: 8+ hours/week | C42: Wellness
A44: ⚡ Total Productive Hours: | B44: ~50 hours/week | C44: Sustainable Pace
...

Sheet Monthly Summary
A1: Metric | B1: January | C1: February | D1: March | E1: Q1 Total
A2: Agentic AI Learning (hrs) | B2: =SUM('Q1 2026 Daily Tracker'!C3:C33) -> 0 | C2: =SUM('Q1 2026 Daily Tracker'!C35:C62) -> 0 | D2: =SUM('Q1 2026 Daily Tracker'!C64:C94) -> 0 | E2: =SUM(B2:D2) -> 0
A3: Work Hours | B3: =SUM('Q1 2026 Daily Tracker'!D3:D33) -> 0 | C3: =SUM('Q1 2026 Daily Tracker'!D35:D62) -> 0 | D3: =SUM('Q1 2026 Daily Tracker'!D64:D94) -> 0 | E3: =SUM(B3:D3) -> 0
A4: Side Hustle Time (hrs) | B4: =SUM('Q1 2026 Daily Tracker'!E3:E33) -> 0 | C4: =SUM('Q1 2026 Daily Tracker'!E35:E62) -> 0 | D4: =SUM('Q1 2026 Daily Tracker'!E64:E94) -> 0 | E4: =SUM(B4:D4) -> 0
A5: Pages Read | B5: =SUM('Q1 2026 Daily Tracker'!F3:F33) -> 0 | C5: =SUM('Q1 2026 Daily Tracker'!F35:F62) -> 0 | D5: =SUM('Q1 2026 Daily Tracker'!F64:F94) -> 0 | E5: =SUM(B5:D5) -> 0
A6: Gym Sessions | B6: =COUNTIF('Q1 2026 Daily Tracker'!G3:G33,"<>") -> 0 | C6: =COUNTIF('Q1 2026 Daily Tracker'!G35:G62,"<>") -> 0 | D6: =COUNTIF('Q1 2026 Daily Tracker'!G64:G94,"<>") -> 0 | E6: =SUM(B6:D6) -> 0
A7: Avg Sleep (hrs) | B7: =AVERAGE('Q1 2026 Daily Tracker'!H3:H33) -> #DIV/0! | C7: =AVERAGE('Q1 2026 Daily Tracker'!H35:H62) -> #DIV/0! | D7: =AVERAGE('Q1 2026 Daily Tracker'!H64:H94) -> #DIV/0! | E7: =AVERAGE(B7:D7) -> #DIV/0!
A8: Avg Water (L) | B8: =AVERAGE('Q1 2026 Daily Tracker'!I3:I33) -> #DIV/0! | C8: =AVERAGE('Q1 2026 Daily Tracker'!I35:I62) -> #DIV/0! | D8: =AVERAGE('Q1 2026 Daily Tracker'!I64:I94) -> #DIV/0! | E8: =AVERAGE(B8:D8) -> #DIV/0!
A9: Meditation (min) | B9: =SUM('Q1 2026 Daily Tracker'!J3:J33) -> 0 | C9: =SUM('Q1 2026 Daily Tracker'!J35:J62) -> 0 | D9: =SUM('Q1 2026 Daily Tracker'!J64:J94) -> 0 | E9: =SUM(B9:D9) -> 0
A11: Days Completed | B11: =COUNTIF('Q1 2026 Daily Tracker'!L3:L33,">0") -> 0 | C11: =COUNTIF('Q1 2026 Daily Tracker'!L35:L62,">0") -> 0 | D11: =COUNTIF('Q1 2026 Daily Tracker'!L64:L94,">0") -> 0 | E11: =SUM(B11:D11) -> 0
A12: Avg Daily Score | B12: =AVERAGE('Q1 2026 Daily Tracker'!L3:L33) -> #DIV/0! | C12: =AVERAGE('Q1 2026 Daily Tracker'!L35:L62) -> #DIV/0! | D12: =AVERAGE('Q1 2026 Daily Tracker'!L64:L94) -> #DIV/0! | E12: =AVERAGE(B12:D12) -> #DIV/0!
A13: Best Streak (days)

Sheet Weekly View
A1: Week | B1: Mon | C1: Tue | D1: Wed | E1: Thu | F1: Fri | G1: Sat | H1: Sun | I1: Total Hrs | J1: Avg Score | K1: Wins | L1: Notes
A2: Week 1 (Jan 1-5)
A3: Week 2 (Jan 6-12)
A4: Week 3 (Jan 13-19)
A5: Week 4 (Jan 20-26)
A6: Week 5 (Jan 27-Feb 2)
A7: Week 6 (Feb 3-9)
A8: Week 7 (Feb 10-16)
A9: Week 8 (Feb 17-23)
A10: Week 9 (Feb 24-Mar 2)
A11: Week 10 (Mar 3-9)
A12: Week 11 (Mar 10-16)
A13: Week 12 (Mar 17-23)
A14: Week 13 (Mar 24-30)

Sheet Goals & Milestones
A1: Category | B1: Goal | C1: Target | D1: Status
A2: 🚀 AGENTIC AI LEARNING
A3: Month 1 Milestone | B3: Complete Document Q&A Agent + GitHub portfolio | C3: Jan 31 | D3: ☐
A4: Month 2 Milestone | B4: Build 3 tool-using agents (weather, email, web) | C4: Feb 28 | D4: ☐
A5: Month 3 Milestone | B5: Deploy production-ready multi-agent system | C5: Mar 31 | D5: ☐
A6: Q1 Learning | B6: Complete 180 hours of learning (2hrs/day) | C6: 180 hrs | D6: ☐
A8: 💼 SIDE HUSTLE
A9: Revenue Goal | B9: First paying customer or product launch | C9: $1 | D9: ☐
A10: Portfolio | B10: Minimum 5 projects on GitHub | C10: 5 projects | D10: ☐
A11: Network | B11: Connect with 50 people in AI community | C11: 50 people | D11: ☐
A12: Content | B12: Post 30 times on LinkedIn about your journey | C12: 30 posts | D12: ☐
A14: 📚 READING
A15: Q1 Reading | B15: Read 900 pages (10 pages/day) | C15: 900 pages | D15: ☐
A16: Books to Complete | B16: Finish 3-4 books on AI/business/self-dev | C16: 4 books | D16: ☐
A17: 💰 FINANCIAL GOALS
A18: Emergency Fund
A19: Side Hustle Revenue | B19: Generate first $1,000 from side hustle | C19: $1,000 | D19: ☐
A20: Savings Rate | B20: Save 20% of income each month | C20: 20% | D20: ☐
A21: Investments | B21: Invest $XXX in learning/tools/growth | C21: $XXX | D21: ☐
A24: 💪 FITNESS
A25: Gym Consistency | B25: Workout 60 times in Q1 (5x/week) | C25: 60 sessions | D25: ☐
A26: Weight Goal | B26: Lose/Gain [YOUR TARGET] kg | C26: X kg | D26: ☐
A28: 🧘 WELLNESS
A29: Sleep | B29: Average 7+ hours of sleep | C29: 7 hrs | D29: ☐
A30: Hydration | B30: Drink 2L+ water daily | C30: 2L/day | D30: ☐
A31: Meditation | B31: Meditate 900 minutes in Q1 | C31: 900 min | D31: ☐
A33: 🎯 OVERALL
A34: Daily Score | B34: Maintain 80+ average score | C34: 80+ | D34: ☐
A35: Consistency | B35: Complete 80+ days (89% success rate) | C35: 80 days | D35: ☐

Sheet How to Use
A1: 📊 Q1 2026 HABIT TRACKER - USER GUIDE
A3: 🎯 DAILY TRACKING (Main Sheet)
A4: Fill in your daily activities each evening or next morning:
A6: • Agentic AI: Hours spent learning/building (target: 2+ hrs)
A7: • Work: Professional work hours (track to avoid burnout)
A8: • Side Hustle: Time on your side project/business (target: 1+ hr)
A9: • Reading: Pages read (target: 10+ pages/day)
A10: • Gym: Type "✓" or minutes worked out (target: 5x/week)
A11: • Sleep: Hours of sleep (target: 7+ hrs)
A12: • Water: Liters consumed (target: 2+ L)
A13: • Meditation: Minutes meditated (target: 10+ min)
A14: • Notes/Wins: Daily highlight, achievement, or reflection
... A44: Remember: Progress > Perfection. Keep going! 💪
